<?xml version='1.0'?>

<robot name="slam_project" xmlns:xacro="http://www.ros.org/wiki/xacro">

  <xacro:include filename="$(find slam_project)/urdf/slam_project.gazebo" />

  <link name="base_footprint"></link>

  <joint name="base_footprint_joint" type="fixed">
    <origin xyz="0 0 0" rpy="0 0 0" />
    <parent link="base_footprint"/>
    <child link="chassis" />
  </joint>

  <link name='chassis'>
    <pose>0 0 0.1 0 0 0</pose>

    <inertial>
      <mass value="15.0"/>
      <origin xyz="0.0 0 0" rpy=" 0 0 0"/>
      <inertia
          ixx="0.1" ixy="0" ixz="0"
          iyy="0.1" iyz="0"
          izz="0.1"
      />
    </inertial>

    <collision name='collision'>
      <origin xyz="0 0 0" rpy=" 0 0 0"/> 
      <geometry>
        <cylinder length="0.1" radius="0.1"/>
      </geometry>
    </collision>

    <visual name='chassis_visual'>
      <origin xyz="0 0 0" rpy=" 0 0 0"/>
      <geometry>
        <cylinder length="0.1" radius="0.1"/>
      </geometry>
    </visual>


    <collision name='back_caster_collision'>
      <origin xyz="-0.15 0 -0.05" rpy=" 0 0 0"/>
      <geometry>
        <sphere radius="0.05"/>
      </geometry>
      <surface>
        <friction>
          <ode>
            <mu>0</mu>
            <mu2>0</mu2>
            <slip1>1.0</slip1>
            <slip2>1.0</slip2>
          </ode>
        </friction>
      </surface>
    </collision>

    <visual name='back_caster_visual'>
      <origin xyz="-0.15 0 -0.05" rpy=" 0 0 0"/>
      <geometry>
        <sphere radius="0.05"/>
      </geometry>
    </visual>

    <collision name='front_caster_collision'>
      <origin xyz="0.15 0 -0.05" rpy=" 0 0 0"/>
      <geometry>
        <sphere radius="0.05"/>
      </geometry>
      <surface>
        <friction>
          <ode>
            <mu>0</mu>
            <mu2>0</mu2>
            <slip1>1.0</slip1>
            <slip2>1.0</slip2>
          </ode>
        </friction>
      </surface>
    </collision>

    <visual name='front_caster_visual'>
      <origin xyz="0.15 0 -0.05" rpy=" 0 0 0"/>
      <geometry>
        <sphere radius="0.05"/>
      </geometry>
    </visual>

  </link>


  <link name="left_wheel">
    <inertial>
      <mass value="5.0"/>
      <origin xyz="0.0 0 0" rpy=" 0 1.5707 1.5707"/>
      <inertia
          ixx="0.1" ixy="0" ixz="0"
          iyy="0.1" iyz="0"
          izz="0.1"
      />
    </inertial>
    <visual name='cylindrical'>
      <origin xyz="0 0 0" rpy=" 0 1.5707 1.5707"/>
      <geometry>
        <cylinder radius="0.1" length="0.05"/>
      </geometry>    
    </visual>
    <collision name='collision'>
      <origin xyz="0 0 0" rpy=" 0 1.5707 1.5707"/>
      <geometry>
        <cylinder radius="0.1" length="0.05"/>
      </geometry>
    </collision>
  </link>


  <link name="right_wheel">
    <inertial>
      <mass value="5.0"/>
      <origin xyz="0.0 0 0" rpy=" 0 1.5707 1.5707"/>
      <inertia
          ixx="0.1" ixy="0" ixz="0"
          iyy="0.1" iyz="0"
          izz="0.1"
      />
    </inertial>
    <visual name='cylindrical'>
      <origin xyz="0 0 0" rpy=" 0 1.5707 1.5707"/>
      <geometry>
        <cylinder radius="0.1" length="0.05"/>
      </geometry>
    </visual>
    <collision name='collision'>
      <origin xyz="0 0 0" rpy=" 0 1.5707 1.5707"/>
      <geometry>
        <cylinder radius="0.1" length="0.05"/>
      </geometry>
    </collision>
  </link>


  <joint type="continuous" name="left_wheel_hinge">
     <origin xyz="0 0.15 0" rpy="0 0 0"/>
     <child link="left_wheel"/>
     <parent link="chassis"/>
     <axis xyz="0 1 0" rpy="0 0 0"/>
     <limit effort="10000" velocity="1000"/>
     <joint_properties damping="1.0" friction="1.0"/>
  </joint>


  <joint type="continuous" name="right_wheel_hinge">
     <origin xyz="0 -0.15 0" rpy="0 0 0"/>
     <child link="right_wheel"/>
     <parent link="chassis"/>
     <axis xyz="0 1 0" rpy="0 0 0"/>
     <limit effort="10000" velocity="1000"/>
     <joint_properties damping="1.0" friction="1.0"/> 
  </joint>


  <link name="camera_link">
    <inertial>
      <mass value="0.1"/>
      <origin xyz="0.0 0 0" rpy=" 0 0 0"/>
      <inertia
          ixx="1e-6" ixy="0" ixz="0"
          iyy="1e-6" iyz="0"
          izz="1e-6"
      />
    </inertial>
    <visual name='box'>
      <origin xyz="0 0 0" rpy=" 0 0 0"/>
      <geometry>
        <box size="0.05 0.05 0.05"/>
      </geometry>
    </visual>
    <collision name='collision'>
      <origin xyz="0 0 0" rpy=" 0 0 0"/>
        <geometry>
          <box size="0.05 0.05 0.05"/>
        </geometry>
    </collision>
  </link>


  <joint type="fixed" name="camera_joint">
     <origin xyz="0.2 0 0.0" rpy="0 0 0"/>
     <child link="camera_link"/>
     <parent link="chassis"/>
     <!--axis xyz="0 0 0" rpy="0 0 0"/>-->
  </joint>


  <link name="camera_rgbd_frame">
   <inertial>
     <mass value="0.001" />
     <origin xyz="0 0 0" />
     <inertia
          ixx="1e-6" ixy="0" ixz="0"
          iyy="1e-6" iyz="0"
          izz="1e-6"
     />
   </inertial>
  </link>


  <joint type="fixed" name="camera_rgbd_joint" >
    <origin xyz="0.001 0 0.001" rpy="0 0 0"/>
    <child link="camera_rgbd_frame" />
    <parent link="camera_link"/>
  </joint>


  <link name="camera_optical_link">
   <inertial>
     <mass value="0.001" />
     <origin xyz="0 0 0" />
     <inertia
          ixx="1e-6" ixy="0" ixz="0"
          iyy="1e-6" iyz="0"
          izz="1e-6"
     />
   </inertial>
  </link>


  <joint type="fixed" name="camera_optical_joint" >
    <origin xyz="0 0 0" rpy="-1.57 0 -1.57"/>
    <child link="camera_optical_link" />
    <parent link="camera_rgbd_frame"/>
  </joint>


  <link name="hokuyo">
    <inertial>
      <mass value="0.1"/>
      <origin xyz="0.0 0 0" rpy=" 0 0 0"/>
      <inertia
          ixx="1e-6" ixy="0" ixz="0"
          iyy="1e-6" iyz="0"
          izz="1e-6"
      />
    </inertial>
    <visual name='mesh'>
      <origin xyz="0 0 0" rpy=" 0 0 0"/>
      <geometry>
        <mesh filename="package://slam_project/meshes/hokuyo.dae"/>
      </geometry>
    </visual>
    <collision name='collision'>
       <origin xyz="0 0 0" rpy=" 0 0 0"/>
         <geometry>
           <box size="0.1 0.1 0.1"/>
         </geometry>
    </collision>
  </link>


  <joint type="fixed" name="hokuyo_joint">
    <origin xyz="0.15 0 0.1" rpy="0 0 0"/>
    <child link="hokuyo"/>
    <parent link="chassis"/>
    <!--axis xyz="0 0 0" rpy="0 0 0"/>-->
  </joint>


</robot>

